Workbook

Sheet Read me
A1: Business Simulator — cost-effectiveness model
A3: A staged selection pipeline that uses a free, offline business simulator as a first-stage filter, a forecast-style business plan as the second, and a six-month review of forecast against actual as the third.
A5: READ THIS FIRST. No part of this pipeline has been run. The simulator exists and is playable; the portal, the backend and the AI marking do not. Every behavioural rate here — how many finish, how many apply, how many firms transform — is a guess with no data behind it. The model is here to show what the answer depends on, not to claim a result.
A7: HOW TO USE IT. Shaded cells on the Inputs sheet are the only things to change. Everything on Calculation and Results is a live formula; edit an input and the whole model moves. Nothing is hardcoded except the inputs themselves.
A9: SOURCE TAGS, on every input:
A10: owner — stated by the project owner and recorded in the decision log.
A11: sourced — taken from a named external source, cited in the note column.
A12: assumption — chosen to make the model run. No evidence behind it.
A13: unverified — recalled from the literature and NOT checked against a source.
A14: Do not repeat these as fact.
A16: BENCHMARK. Following GiveWell, cost-effectiveness is expressed as a multiple of unconditional cash transfers to people in poverty. GiveWell's stated funding bar is 6× that benchmark. Both are on the Results sheet.
A18: GiveWell's own caveat applies with more force here than it does to them: these estimates are extremely rough and should not be taken literally. They are for comparing options, not for predicting outcomes.
A20: Generated by scripts/build-model-xlsx.py. Do not edit this workbook by hand — regenerate it. The same arithmetic generates docs/concept-note.html.

Sheet Inputs
A1: Inputs — shaded cells are the ones to change
A2: Parameter | B2: Value | C2: Source | D2: Note
A3: Stage-0 starts in the pilot | B3: 3000 | C3: assumption | D3: Nobody has chosen a recruitment channel yet (Q-039).
A4: Share of starts that finish chapter 1 | B4: 0.35 | C4: assumption | D4: Untested. No completion data exists for any build.
A5: Share of finishers who submit a forecast | B5: 0.2 | C5: assumption | D5: The portal does not exist yet (Q-035).
A6: Grants awarded at stage 1 | B6: 50 | C6: owner | D6: USD 50,000 ÷ 1,000 (D-035).
A7: Stage-1 grant, USD | B7: 1000 | C7: owner | D7: D-034.
A8: Recruitment cost per stage-0 start, USD | B8: 2 | C8: assumption | D8: Blended word-of-mouth and paid; wholly channel-dependent.
A9: One-off build: portal, backend, AI judge, USD | B9: 100 | C9: owner | D9: Built with an AI coding agent, not a dev team. Owner's figure.
A10: AI marking cost per submission, USD | B10: 0.01 | C10: owner | D10: Owner's figure. Model inference, including follow-up probes.
A11: Six-month review per funded firm, USD | B11: 150 | C11: assumption | D11: Mostly asynchronous: photos, portal, one call.
A12: Hosting and data for one cohort, USD | B12: 200 | C12: assumption | D12: Stage 0 is a static PWA; this is close to a floor.
A13: Programme administration overhead | B13: 0.15 | C13: assumption
A14: Share of funded firms that become transformational | B14: 0.06 | C14: assumption | D14: THE critical unknown. The pilot exists to measure it (Q-034).
A15: Jobs at the point of the grant | B15: 5 | C15: assumption | D15: Where the firm starts, not where it ends.
A16: Annual growth in jobs | B16: 0.12 | C16: assumption | D16: Building an organisation larger than the founder is the definition of transformational (AGENTS.md §2).
A17: Annual survival probability, transformational firm | B17: 0.92 | C17: assumption | D17: Replaces a hard cut-off year. A firm still trading keeps producing.
A18: Horizon, transformational firm | B18: 15 | C18: assumption | D18: Survival does the decaying; the horizon only bounds the sum.
A19: Annual income gain per job, USD | B19: 600 | C19: assumption | D19: Gain over the counterfactual occupation, not the wage.
A20: Owner's own net income gain, as a share of the worker income-gain base | B20: 0.35 | C20: assumption | D20: Net of tax, so it does not double-count the tax line.
A21: Tax paid, as a share of the worker income-gain base | B21: 0.25 | C21: assumption | D21: Formalisation is what chapters 3–4 teach. Paid out of profit, so no double count with owner income.
A22: Value of $1 of public revenue vs $1 of private income | B22: 1 | C22: assumption | D22: 1.0 treats tax as neutral. Argue up for public goods, down for leakage. Set to 0 to exclude tax entirely.
A23: Local supplier income gain, as a share of the worker income-gain base | B23: 0.3 | C23: assumption | D23: Backward linkages — the firm buys inputs from local suppliers and develops them.
A24: Displacement share — transformational firm | B24: 0.15 | C24: assumption | D24: Lower than a livelihood firm: new markets and exports displace less than another shop on the same street.
A25: Share of transformational outcomes that would have happened anyway | B25: 0.5 | C25: assumption | D25: These are, by selection, the most capable applicants.
A26: Annual income gain, non-transformational funded firm, USD | B26: 450 | C26: assumption | D26: Capital stays in a working business rather than being consumed.
A27: Annual survival probability, other funded firm | B27: 0.85 | C27: assumption
A28: Horizon, other funded firm | B28: 8 | C28: assumption
A29: Displacement share — livelihood firm | B29: 0.4 | C29: assumption | D29: High: mostly competing for the same local customers.
A30: Counterfactual share for non-transformational firms | B30: 0.2 | C30: assumption
A31: Annual income gain per unfunded finisher, USD | B31: 12 | C31: assumption | D31: Small per head, large N. Genuinely unmeasured.
A32: Years the learning gain persists | B32: 2 | C32: assumption
A33: Uncertainty haircut on the learning effect | B33: 0.5 | C33: assumption | D33: Generic business training has a weak evidence base.
A34: Annual income gain from a USD 1,000 cash transfer | B34: 270 | C34: unverified | D34: Roughly GiveDirectly-shaped. NOT checked against a source.
A35: GiveWell funding bar, multiples of the cash benchmark | B35: 6 | C35: sourced | D35: givewell.org, cost-effectiveness models page, stated as of May 2026.
A36: Years the cash-transfer gain persists | B36: 3 | C36: unverified
A37: Stage-2 fixed tranche, USD | B37: 10000 | C37: assumption | D37: Owner: the least that reveals absorptive capacity (D-038).
A38: Share of stage-1 firms advancing to stage 2 | B38: 0.24 | C38: assumption
A39: Stage-3 fixed tranche, USD | B39: 60000 | C39: assumption
A40: Share of stage-2 firms advancing to stage 3 | B40: 0.25 | C40: assumption
...

Sheet Calculation
A1: Calculation — every step, live
A2: Step | B2: Formula | C2: Value | D2: Note
A4: 1 · Funnel
A5: People reached | B5: = Inputs!B3 | C5: =Inputs!B3 -> 3000
A6: Finish chapter 1 | B6: = C5*Inputs!B4 | C6: =C5*Inputs!B4 -> 1050
A7: Submit a forecast through the portal | B7: = C6*Inputs!B5 | C7: =C6*Inputs!B5 -> 210
A8: Funded | B8: = MIN(Inputs!B6,C7) | C8: =MIN(Inputs!B6,C7) -> 50
A9: Selection ratio | B9: = C8/C7 | C9: =C8/C7 -> 0.23809524
A10: Finishers who receive nothing | B10: = C6-C8 | C10: =C6-C8 -> 1000
A12: 2 · Cost
A13: Grants | B13: = C8*Inputs!B7 | C13: =C8*Inputs!B7 -> 50000
A14: Recruitment | B14: = C5*Inputs!B8 | C14: =C5*Inputs!B8 -> 6000
A15: Six-month reviews | B15: = C8*Inputs!B11 | C15: =C8*Inputs!B11 -> 7500
A16: Hosting | B16: = Inputs!B12 | C16: =Inputs!B12 -> 200
A17: Platform build (one-off) | B17: = Inputs!B9 | C17: =Inputs!B9 -> 100 | D17: AI-built, not a dev team.
A18: AI marking | B18: = C7*Inputs!B10 | C18: =C7*Inputs!B10 -> 2.1
A19: Subtotal | B19: = SUM(C13:C18) | C19: =SUM(C13:C18) -> 63802.1
A20: Administration | B20: = C19*Inputs!B13 | C20: =C19*Inputs!B13 -> 9570.315
A21: TOTAL COST | B21: = C19+C20 | C21: =C19+C20 -> 73372.415
A23: 3 · Benefit — transformational firms
A24: Transformational firms | B24: = C8*Inputs!B14 | C24: =C8*Inputs!B14 -> 3
A25: Worker income gain, year 1 | B25: = Inputs!B15*Inputs!B19 | C25: =Inputs!B15*Inputs!B19 -> 3000
A26: PV factor — grows, survives, bounded by the horizon | B26: = (1/(1+Inputs!B43))*(1-(((1+Inputs!B16)*Inputs!B17/(1+Inputs!B43))^Inputs!B18))/(1-((1+Inputs!B16)*Inputs!B17/(1+Inputs!B43))) | C26: =(1/(1+Inputs!B43))*(1-(((1+Inputs!B16)*Inputs!B17/(1+Inputs!B43))^Inputs!B18))/(1-((1+Inputs!B16)*Inputs!B17/(1+Inputs!B43))) -> 12.561921 | D26: Growth and survival together, rather than a hard cut-off year.
A27: PV of worker income gains | B27: = C25*C26 | C27: =C25*C26 -> 37685.764
A28: + owner's own net income | B28: = C27*Inputs!B20 | C28: =C27*Inputs!B20 -> 13190.017
A29: + tax paid once formal | B29: = C27*Inputs!B21*Inputs!B22 | C29: =C27*Inputs!B21*Inputs!B22 -> 9421.441 | D29: Set public_value to 0 to exclude tax entirely.
A30: + local supplier income | B30: = C27*Inputs!B23 | C30: =C27*Inputs!B23 -> 11305.729
A31: Gross PV per firm | B31: = C27+C28+C29+C30 | C31: =C27+C28+C29+C30 -> 71602.952
A32: less displacement and counterfactual | B32: = C31*(1-Inputs!B24)*(1-Inputs!B25) | C32: =C31*(1-Inputs!B24)*(1-Inputs!B25) -> 30431.254
A33: STREAM TOTAL | B33: = C24*C32 | C33: =C24*C32 -> 91293.763
A35: 4 · Benefit — other funded firms
A36: Firms | B36: = C8-C24 | C36: =C8-C24 -> 47
A37: PV factor — survives, bounded by the horizon | B37: = (1/(1+Inputs!B43))*(1-((Inputs!B27/(1+Inputs!B43))^Inputs!B28))/(1-(Inputs!B27/(1+Inputs!B43))) | C37: =(1/(1+Inputs!B43))*(1-((Inputs!B27/(1+Inputs!B43))^Inputs!B28))/(1-(Inputs!B27/(1+Inputs!B43))) -> 4.0778384
A38: STREAM TOTAL | B38: = C36*Inputs!B26*C37*(1-Inputs!B29)*(1-Inputs!B30) | C38: =C36*Inputs!B26*C37*(1-Inputs!B29)*(1-Inputs!B30) -> 41398.216 | D38: Not a cash transfer: selection plus discipline.
A40: 5 · Benefit — learning, among finishers who get nothing
A41: PV factor | B41: = (1-(1+Inputs!B43)^-Inputs!B32)/Inputs!B43 | C41: =(1-(1+Inputs!B43)^-Inputs!B32)/Inputs!B43 -> 1.8594104
A42: STREAM TOTAL | B42: = C10*Inputs!B31*C41*Inputs!B33 | C42: =C10*Inputs!B31*C41*Inputs!B33 -> 11156.463 | D42: Large N, tiny per head, genuinely unmeasured.
A44: 6 · Cash benchmark
A45: PV factor | B45: = (1-(1+Inputs!B43)^-Inputs!B36)/Inputs!B43 | C45: =(1-(1+Inputs!B43)^-Inputs!B36)/Inputs!B43 -> 2.723248
A46: PV income per $1 of unconditional cash | B46: = Inputs!B34*C45/1000 | C46: =Inputs!B34*C45/1000 -> 0.73527697 | D46: Benchmark. Input is unverified.
...

Sheet Results
A1: Results
A2: Output | B2: Value | C2: Reading
A3: Total cost of the pilot | B3: =Calculation!C21 -> 73372.415 | C3: Of which 68% reaches founders as cash.
A4: Total PV benefit | B4: =Calculation!C49 -> 143848.44 | C4: Three streams: transformational firms, other funded firms, learning.
A5: PV income per $1 spent | B5: =Calculation!C50 -> 1.9605248
A6: Unconditional cash benchmark | B6: =Calculation!C46 -> 0.73527697 | C6: PV income per $1 of cash handed over. Input is unverified.
A7: MULTIPLE OF CASH | B7: =Calculation!C51 -> 2.666376 | C7: The headline number, in GiveWell's units.
A8: GiveWell funding bar | B8: =Inputs!B35 -> 6 | C8: Their stated bar for making a grant, as of May 2026.
A9: Hit rate needed to match cash | B9: =Calculation!C52 -> 0.00091640551 | C9: Share of funded firms that must become transformational.
A10: Hit rate needed to clear 6× | B10: =Calculation!C53 -> 0.17819811 | C10: The honest test. Compare against what you believe is achievable.
A11: Cost per transformational firm | B11: =Calculation!C54 -> 24457.472
A13: What this says
A14: At the base-case hit rate of 6%, the pipeline lands at 2.67× unconditional cash. It matches cash at a 0.1% hit rate and would need 18% to clear GiveWell's bar.
A16: The sensitivity sheet is the real finding: the result is dominated by the hit rate and by jobs per firm. Recruitment cost, completion rate and the platform build barely move it. This is a venture portfolio, not a service-delivery programme, and it should be argued for and evaluated as one.
A18: The pilot's largest output is not the firms funded. It is the only dataset that could ever tell you what the hit rate actually is — which is worth far more than one cohort's direct benefit, and is destroyed if every grant goes to the highest-ranked applicant.

Sheet Ladder
A1: How much of the benefit is counted
A2: Each row adds one component to the row above it.
A3: What is counted | B3: PV per $1 | C3: × cash | D3: Why
A4: Wages only, and they stop after 6 years | B4: 0.46 | C4: 0.63 | D4: The original reading. A fixed worker income-gain base for a fixed period, nothing else.
A5: + the firm survives and grows | B5: 0.85 | C5: 1.16 | D5: A hard cut-off is the wrong shape. Survival decays the stream; growth is what 'transformational' means.
A6: + the owner's own income | B6: 1.079 | C6: 1.47 | D6: Previously counted at zero, which is plainly wrong.
A7: + tax paid once formal | B7: 1.243 | C7: 1.69 | D7: Valued at par with private income by default. Set public_value to 0 to drop it.
A8: + local suppliers | B8: 1.44 | C8: 1.96 | D8: Backward linkages. The most arguable rung on the ladder.
A9: + livelihood firms are not just cash | B9: 1.808 | C9: 2.46 | D9: Capital that stays in a trading business, in firms that passed a filter and wrote a forecast.
A10: + learning among those who get nothing | B10: 1.961 | C10: 2.67 | D10: Tiny per head, ~1,000 heads, and genuinely unmeasured.
A12: Adding benefit categories is the easiest way to make any programme look good. None of these components is measured. A reader who does not accept a row can stop at the row above it and take that number instead — which is why the ladder is here rather than only the final figure. These are static values: each requires re-running the model with several inputs changed at once.

Sheet Sensitivity
A1: Sensitivity — one parameter at a time, across its plausible range
A2: Parameter | B2: Low | C2: High | D2: Ratio at low | E2: Ratio at high | F2: Swing
A3: Annual growth in jobs | B3: 0 | C3: 0.25 | D3: 1.373 | E3: 3.603 | F3: 2.229
A4: Share of funded firms that become transformational | B4: 0.02 | C4: 0.12 | D4: 1.155 | E4: 3.169 | F4: 2.014
A5: Jobs at the point of the grant | B5: 2 | C5: 10 | D5: 1.214 | E5: 3.205 | F5: 1.991
A6: Annual survival probability, transformational firm | B6: 0.8 | C6: 0.97 | D6: 1.3 | E6: 2.532 | F6: 1.232
A7: Annual income gain per job, USD | B7: 400 | C7: 900 | D7: 1.546 | E7: 2.583 | F7: 1.037
A8: Share of transformational outcomes that would have happened anyway | B8: 0.7 | C8: 0.3 | D8: 1.463 | E8: 2.458 | F8: 0.995
A9: Horizon, transformational firm | B9: 8 | C9: 20 | D9: 1.423 | E9: 2.303 | F9: 0.88
A10: One-off build: portal, backend, AI judge, USD | B10: 40000 | C10: 100 | D10: 1.206 | E10: 1.961 | F10: 0.754
A11: Annual income gain, non-transformational funded firm, USD | B11: 200 | C11: 700 | D11: 1.647 | E11: 2.274 | F11: 0.627
A12: Displacement share — transformational firm | B12: 0.4 | C12: 0.05 | D12: 1.595 | E12: 2.107 | F12: 0.512
A13: Local supplier income gain, as a share of the worker income-gain base | B13: 0 | C13: 0.6 | D13: 1.764 | E13: 2.157 | F13: 0.393
A14: Owner's own net income gain, as a share of the worker income-gain base | B14: 0 | C14: 0.6 | D14: 1.731 | E14: 2.124 | F14: 0.393
... A20: Share of finishers who submit a forecast | B20: 0.1 | C20: 0.35 | D20: 1.961 | E20: 1.96 | F20: 0
A22: These columns are static values, not formulas: each one requires re-running the whole model with a single input changed, which a spreadsheet cannot express in one cell. To check any row by hand, change that input on the Inputs sheet and read the Results sheet.
